Workbook
Name Excel_BuiltIn_Print_Area_1: "$#REF!.$B$2:$AT$212"
Name Excel_BuiltIn_Print_Area_1_1: "$#REF!.$B$2:$AT$197"
Name Excel_BuiltIn_Print_Area_10_1: "$'07'.$#REF!$#REF!:$#REF!$#REF!"
Name Excel_BuiltIn_Print_Area_10_1_1: "$'06'.$#REF!$#REF!:$#REF!$#REF!"
Name Excel_BuiltIn_Print_Area_10_1_1_1: "$'06'.$#REF!$#REF!:$#REF!$#REF!"
Name Excel_BuiltIn_Print_Area_11_1: "$'05'.$#REF!$#REF!:$#REF!$#REF!"
Name Excel_BuiltIn_Print_Area_11_1_1: "$'05'.$#REF!$#REF!:$#REF!$#REF!"
Name Excel_BuiltIn_Print_Area_11_1_1_1: "$'05'.$#REF!$#REF!:$#REF!$#REF!"
Name Excel_BuiltIn_Print_Area_12: "$#REF!.$A$1:$I$153"
Name Excel_BuiltIn_Print_Area_12_1: "$'04'.$#REF!$#REF!:$#REF!$#REF!"
Name Excel_BuiltIn_Print_Area_12_1_1: "$'04'.$#REF!$#REF!:$#REF!$#REF!"
Name Excel_BuiltIn_Print_Area_12_1_1_1: "$'04'.$#REF!$#REF!:$#REF!$#REF!"
Name Excel_BuiltIn_Print_Area_13: "$#REF!.$A$1:$I$93"
Name Excel_BuiltIn_Print_Area_13_1: "$'03'.$#REF!$#REF!:$#REF!$#REF!"
Name Excel_BuiltIn_Print_Area_13_1_1: "$'03'.$#REF!$#REF!:$#REF!$#REF!"
Name Excel_BuiltIn_Print_Area_14: "$'02'.$#REF!$#REF!:$#REF!$#REF!"
Name Excel_BuiltIn_Print_Area_14_1: "$'02'.$#REF!$#REF!:$#REF!$#REF!"
Name Excel_BuiltIn_Print_Area_15: "$'01'.$#REF!$#REF!:$#REF!$#REF!"
Name Excel_BuiltIn_Print_Area_16: "$#REF!.$A$1:$I$151"
Name Excel_BuiltIn_Print_Area_16_1: "$#REF!.$A$1:$I$188"
Name Excel_BuiltIn_Print_Area_18_1: "$#REF!.$A$1:$N$7"
Name Excel_BuiltIn_Print_Area_19_1: #REF!
Name Excel_BuiltIn_Print_Area_19_1: #REF!
Name Excel_BuiltIn_Print_Area_19_1: #REF!
Name Excel_BuiltIn_Print_Area_19_1: #REF!
Name Excel_BuiltIn_Print_Area_19_1: #REF!
Name Excel_BuiltIn_Print_Area_19_1: #REF!
Name Excel_BuiltIn_Print_Area_2_1: "$#REF!.$A$2:$AS$207"
Name Excel_BuiltIn_Print_Area_2_1_1: "$#REF!.$B$2:$FZ$233"
Name Excel_BuiltIn_Print_Area_2_1_1_1: "$'14'.$#REF!$#REF!:$#REF!$#REF!"
Name Excel_BuiltIn_Print_Area_2_1_1_1_1: "$#REF!.$A$1:$I$41"
Name Excel_BuiltIn_Print_Area_2_1_1_1_1_1: "$#REF!.$A$1:$I$3"
Name Excel_BuiltIn_Print_Area_20_1: #REF!
Name Excel_BuiltIn_Print_Area_20_1: #REF!
Name Excel_BuiltIn_Print_Area_20_1: #REF!
Name Excel_BuiltIn_Print_Area_20_1: #REF!
Name Excel_BuiltIn_Print_Area_20_1: #REF!
Name Excel_BuiltIn_Print_Area_20_1: #REF!
Name Excel_BuiltIn_Print_Area_20_1_1: "$#REF!.$A$1:$AO$6"
Name Excel_BuiltIn_Print_Area_20_1_1_1: "$#REF!.$A$1:$AN$6"
Name Excel_BuiltIn_Print_Area_20_1_1_1_1: "$#REF!.$A$1:$H$7"
Name Excel_BuiltIn_Print_Area_21_1: "$#REF!.$A$1:$AN$6"
Name Excel_BuiltIn_Print_Area_21_1_1: "$#REF!.$A$1:$AS$206"
Name Excel_BuiltIn_Print_Area_21_1_1_1: "$#REF!.$#REF!$#REF!:$#REF!$#REF!"
Name Excel_BuiltIn_Print_Area_22_1: #REF!
Name Excel_BuiltIn_Print_Area_22_1: #REF!
Name Excel_BuiltIn_Print_Area_22_1: #REF!
Name Excel_BuiltIn_Print_Area_22_1: #REF!
Name Excel_BuiltIn_Print_Area_22_1: #REF!
Name Excel_BuiltIn_Print_Area_22_1: #REF!
Name Excel_BuiltIn_Print_Area_22_1_1: #REF!
Name Excel_BuiltIn_Print_Area_22_1_1: #REF!
Name Excel_BuiltIn_Print_Area_22_1_1: #REF!
Name Excel_BuiltIn_Print_Area_22_1_1: #REF!
Name Excel_BuiltIn_Print_Area_22_1_1: #REF!
Name Excel_BuiltIn_Print_Area_22_1_1: #REF!
Name Excel_BuiltIn_Print_Area_22_1_1_1: "$#REF!.$A$1:$AO$6"
Name Excel_BuiltIn_Print_Area_22_1_1_1_1: "$#REF!.$A$1:$AN$6"
Name Excel_BuiltIn_Print_Area_22_1_1_1_1_1: #REF!
Name Excel_BuiltIn_Print_Area_22_1_1_1_1_1: #REF!

Sheet Sheet2
A1: NO | B1: JENIS SURAT | C1: PERIHAL | D1: NAMA | E1: BERLAKU | F1: LEVEL | G1: KATEGORI
A2: 1 | B2: Surat Keputusan | C2: Promosi Jabatan | D2: Jefri Boymau | E2: 46143 | F2: 7 | G2: -
A3: 2 | B3: Surat Keputusan | C3: Promosi Jabatan | D3: Guntur Yoso Nasution | E3: 46143 | F3: 7 | G3: -
A4: 3 | B4: Surat Keputusan | C4: Promosi Jabatan | D4: Dhinar Sandy Hermansyah | E4: 46146 | F4: 7 | G4: -
A5: 4 | B5: Surat Keputusan | C5: Promosi Jabatan | D5: Bonifasius Sonlai | E5: 46143 | F5: 7 | G5: -
A6: 5 | B6: Surat Keputusan | C6: Promosi Jabatan | D6: James Saban | E6: 46143 | F6: 7 | G6: -
A7: 6 | B7: Surat Keputusan | C7: Promosi Jabatan | D7: Fortunatus Nestor Sakan | E7: 46143 | F7: 7 | G7: -
A8: 7 | B8: Surat Keputusan | C8: Promosi Jabatan | D8: Doni Alexander Tallo | E8: 46143 | F8: 7 | G8: -
A9: 8 | B9: Surat Keputusan | C9: Promosi Jabatan | D9: Sepri Obaja Talan | E9: 46143 | F9: 9 | G9: A
A10: 9 | B10: Surat Pemberitahuan | C10: Perubahan Nama Jabatan & Kenaikan Level Jabatan | D10: Khairuddin | E10: 46143 | F10: 7 | G10: -
A11: 10 | B11: Surat Pemberitahuan | C11: Perubahan Nama Jabatan & Kenaikan Level Jabatan | D11: Henry Agus Widjajanto | E11: 46143 | F11: 11 | G11: -
A12: 11 | B12: Surat Pemberitahuan | C12: Kenaikan Jabatan & Kenaikan Level | D12: Anggi Aruli | E12: 46143 | F12: 11 | G12: -
A13: 12 | B13: Surat Pemberitahuan | C13: Kenaikan Jabatan & Kenaikan Level | D13: Plasidus Uga | E13: 46143 | F13: 13 | G13: -
... A43: 42 | B43: Surat Pemberitahuan | C43: Perubahan Nama Jabatan | D43: Ferianto | E43: 46143 | F43: 7 | G43: A

Sheet HRIS
AC1: Freelance | AF1: Freelance | AO1: Kontrak 3 | BE1: Lama Kerja
A2: NO | B2: PIN | C2: NIK | D2: Area | E2: Nama | F2: Jabatan | G2: Status Pekerjaan | H2: Habis Kontrak | I2: Kategori | J2: Level | K2: Area Rekrut | L2: NIK KTP | M2: No KK | N2: Agama | O2: Tempat Lahir | P2: Tanggal Lahir | Q2: Umur | R2: Alamat | S2: Jenis Kelamin | T2: Status Kawin | U2: Jumlah Anak | V2: Pendidikan | W2: BPJS TK | X2: BPJS KESEHATAN | Y2: No HP | Z2: No Rek BNI | AA2: NPWP | AB2: Email | AC2: 1 | AD2: 2 | AE2: 3 | AF2: 4 | AG2: 5 | AH2: 6 | AI2: PK 1 Awal | AJ2: PK 1 Akhir | AK2: GT 1 | AL2: PK 2 Awal | AM2: PK 2 Akhir | AN2: GT 2 | AO2: PK 3 Awal | AP2: PK 3 Akhir | AQ2: GT 3 | AR2: PK 4 Awal | AS2: PK 4 Akhir | AT2: GT 4 | AU2: PK 5 Awal | AV2: PK 5 Akhir | AW2: GT 5 | AX2: PK 6 Awal | AY2: PK 6 Akhir | AZ2: GT 6 | BA2: PK 7 Awal | BB2: PK 7 Akhir | BC2: GT 7 | BD2: Awal Kontrak berlaku | BE2: YY | BF2: MM | BG2: DD
A3: 1 | B3: 55001 | C3: A01001 | D3: G. Induk | E3: DONNY STEVANUS | F3: Manager Regional Area | G3: =IF(AI3="","Perekrutan",IF(BE3>4,"Tetap",IF(BA3<>"","Kontrak VII",IF(AX3<>"","Kontrak VI",IF(AU3<>"","Kontrak V",IF(AR3<>"","Kontrak IV",IF(AO3<>"","Kontrak III",IF(AL3<>"","Kontrak II",IF(AI3<>"","Kontrak I",""))))))))) -> Tetap | H3: =IF(G3="Tetap","",IF(BA3<>"",BB3,IF(AX3<>"",AY3,IF(AU3<>"",AV3,IF(AR3<>"",AS3,IF(AO3<>"",AP3,IF(AL3<>"",AM3,IF(AI3<>"",AJ3,"")))))))) | K3: Malang | L3: 3507132001830003 | N3: Kristen | O3: Malang | P3: 30336 | Q3: =IF(P3="","",(DATEDIF(P3,TODAY(),"Y"))) -> 43 | R3: Semanding RT 009 RW 004 Desa Curungrejo Kec. Kepanjen Kab. Malang | S3: L | T3: Kawin | U3: K01 | Z3: 1654056600 | AA3: 587497850654000 | AI3: 39896 | AJ3: 40080 | AK3: =IF(AJ3="","",(DATEDIF(AI3,AJ3,"M")+1)) -> 7 | AL3: 40081 | AM3: 40446 | AN3: =IF(AM3="","",(DATEDIF(AL3,AM3,"M")+1)) -> 13 | AQ3: =IF(AP3="","",(DATEDIF(AO3,AP3,"M")+1)) | AT3: =IF(AS3="","",(DATEDIF(AR3,AS3,"M")+1)) | AZ3: =IF(AY3="","",(DATEDIF(AX3,AY3,"M")+1)) | BC3: =IF(BB3="","",(DATEDIF(BA3,BB3,"M")+1)) | BD3: =IF(G3="Tetap","",IF(BA3<>"",BA3,IF(AX3<>"",AX3,IF(AU3<>"",AU3,IF(AR3<>"",AR3,IF(AO3<>"",AO3,IF(AL3<>"",AL3,IF(AI3<>"",AI3,"")))))))) | BE3: =IF($AI3="","0",(DATEDIF($AI3,TODAY(),"Y"))) -> 17 | BF3: =IF($AI3="","",(DATEDIF($AI3,TODAY(),"YM"))) -> 6 | BG3: =IF($AI3="","",(DATEDIF($AI3,TODAY(),"MD"))) -> 9
A4: =A3+1 -> 2 | B4: 55003 | C4: A01003 | D4: G. Induk | E4: RAFICA DWI ANANTA | F4: Admin Gudang Induk merangkap Kepala Gd. Induk | G4: =IF(AI4="","Perekrutan",IF(BE4>4,"Tetap",IF(BA4<>"","Kontrak VII",IF(AX4<>"","Kontrak VI",IF(AU4<>"","Kontrak V",IF(AR4<>"","Kontrak IV",IF(AO4<>"","Kontrak III",IF(AL4<>"","Kontrak II",IF(AI4<>"","Kontrak I",""))))))))) -> Tetap | H4: =IF(G4="Tetap","",IF(BA4<>"",BB4,IF(AX4<>"",AY4,IF(AU4<>"",AV4,IF(AR4<>"",AS4,IF(AO4<>"",AP4,IF(AL4<>"",AM4,IF(AI4<>"",AJ4,"")))))))) | I4: B | J4: 7 | K4: Labuhanbatu-Sumut II | L4: 1271202209790004 | N4: Islam | O4: Rantauprapat | P4: 35060 | Q4: =IF(P4="","",(DATEDIF(P4,TODAY(),"Y"))) -> 30 | R4: Jl Tirta Bina No.103 RT 001 RW 001 Desa Rantauprapat Kec. Rantau Utara Kab. Labuhanbatu Sumut | S4: P | T4: Kawin | U4: K01 | V4: S1 | Z4: 341235821 | AA4: 1210016712950001 | AC4: 02 Mei - 04 Juni 2019 | AI4: 43626 | AJ4: 43809 | AK4: =IF(AJ4="","",(DATEDIF(AI4,AJ4,"M")+1)) -> 7 | AL4: 43810 | AM4: 43993 | AN4: =IF(AM4="","",(DATEDIF(AL4,AM4,"M")+1)) -> 7 | AO4: 43994 | AP4: 44724 | AQ4: =IF(AP4="","",(DATEDIF(AO4,AP4,"M")+1)) -> 25 | AR4: 44725 | AS4: 45473 | AT4: =IF(AS4="","",(DATEDIF(AR4,AS4,"M")+1)) -> 25 | AW4: =IF(AV4="","",(DATEDIF(AU4,AV4,"M")+1)) | AZ4: =IF(AY4="","",(DATEDIF(AX4,AY4,"M")+1)) | BC4: =IF(BB4="","",(DATEDIF(BA4,BB4,"M")+1)) | BD4: =IF(G4="Tetap","",IF(BA4<>"",BA4,IF(AX4<>"",AX4,IF(AU4<>"",AU4,IF(AR4<>"",AR4,IF(AO4<>"",AO4,IF(AL4<>"",AL4,IF(AI4<>"",AI4,"")))))))) | BE4: =IF($AI4="","0",(DATEDIF($AI4,TODAY(),"Y"))) -> 7 | BF4: =IF($AI4="","",(DATEDIF($AI4,TODAY(),"YM"))) -> 3 | BG4: =IF($AI4="","",(DATEDIF($AI4,TODAY(),"MD"))) -> 23
A5: =A4+1 -> 3 | B5: 55004 | C5: A01004 | D5: G. Induk | E5: DINDA KARINA | F5: Administrasi Penjualan & Gudang (Kecil) Area | G5: =IF(AI5="","Perekrutan",IF(BE5>4,"Tetap",IF(BA5<>"","Kontrak VII",IF(AX5<>"","Kontrak VI",IF(AU5<>"","Kontrak V",IF(AR5<>"","Kontrak IV",IF(AO5<>"","Kontrak III",IF(AL5<>"","Kontrak II",IF(AI5<>"","Kontrak I",""))))))))) -> Kontrak IV | H5: =IF(G5="Tetap","",IF(BA5<>"",BB5,IF(AX5<>"",AY5,IF(AU5<>"",AV5,IF(AR5<>"",AS5,IF(AO5<>"",AP5,IF(AL5<>"",AM5,IF(AI5<>"",AJ5,"")))))))) -> 46356 | I5: A | J5: 3 | K5: Kab. Asahan | L5: 1209126505990001 | N5: Islam | O5: Pekan Baru | P5: 36303 | Q5: =IF(P5="","",(DATEDIF(P5,TODAY(),"Y"))) -> 27 | R5: Dusun IV Pulau Maria RT / RW 000 Desa Pulau Maria Kec. Teluk Dalam Kab. Asahan Sumut | S5: P | T5: Belum Kawin | U5: - | V5: S1 Pertanian | Z5: 1888997073 | AA5: 1209126505990001 | AC5: 14 Okt - 12 Nov 2024 | AI5: 45609 | AJ5: 45747 | AK5: =IF(AJ5="","",(DATEDIF(AI5,AJ5,"M")+1)) -> 5 | AL5: 45748 | AM5: 45869 | AN5: =IF(AM5="","",(DATEDIF(AL5,AM5,"M")+1)) -> 4 | AO5: 45870 | AP5: 45991 | AQ5: =IF(AP5="","",(DATEDIF(AO5,AP5,"M")+1)) -> 4 | AR5: 45992 | AS5: 46356 | AT5: =IF(AS5="","",(DATEDIF(AR5,AS5,"M")+1)) -> 12 | AW5: =IF(AV5="","",(DATEDIF(AU5,AV5,"M")+1)) | AZ5: =IF(AY5="","",(DATEDIF(AX5,AY5,"M")+1)) | BC5: =IF(BB5="","",(DATEDIF(BA5,BB5,"M")+1)) | BD5: =IF(G5="Tetap","",IF(BA5<>"",BA5,IF(AX5<>"",AX5,IF(AU5<>"",AU5,IF(AR5<>"",AR5,IF(AO5<>"",AO5,IF(AL5<>"",AL5,IF(AI5<>"",AI5,"")))))))) -> 45992 | BE5: =IF($AI5="","0",(DATEDIF($AI5,TODAY(),"Y"))) -> 1 | BF5: =IF($AI5="","",(DATEDIF($AI5,TODAY(),"YM"))) -> 10 | BG5: =IF($AI5="","",(DATEDIF($AI5,TODAY(),"MD"))) -> 20
A6: =A5+1 -> 4 | D6: G. Induk | E6: YUSUF HAMDANI | F6: Pekerja Gudang | G6: =IF(AI6="","Perekrutan",IF(BE6>4,"Tetap",IF(BA6<>"","Kontrak VII",IF(AX6<>"","Kontrak VI",IF(AU6<>"","Kontrak V",IF(AR6<>"","Kontrak IV",IF(AO6<>"","Kontrak III",IF(AL6<>"","Kontrak II",IF(AI6<>"","Kontrak I",""))))))))) -> Kontrak I | H6: =IF(G6="Tetap","",IF(BA6<>"",BB6,IF(AX6<>"",AY6,IF(AU6<>"",AV6,IF(AR6<>"",AS6,IF(AO6<>"",AP6,IF(AL6<>"",AM6,IF(AI6<>"",AJ6,"")))))))) -> 46326 | K6: Kab. Labuhanbatu | L6: 1210012303010005 | N6: Islam | O6: Rantauprapat | P6: 36973 | Q6: =IF(P6="","",(DATEDIF(P6,TODAY(),"Y"))) -> 25 | R6: Gg. Mesjid Al Musahada / LK. Padat Karya, RT/RW 000, Kel. Bakaran Batu, Kec. Rantau Selatan, Kab. Labuhanbatu | S6: L | T6: Belum Kawin | U6: - | V6: SMA IPS | Z6: 1933247453 | AC6: 22 Apr - 18 Mei 2026 | AD6: 19 Mei - 13 Juni 2026 | AE6: 15 Juni - 08 Juli 2026 | AI6: 46204 | AJ6: 46326 | AK6: =IF(AJ6="","",(DATEDIF(AI6,AJ6,"M")+1)) -> 4 | AN6: =IF(AM6="","",(DATEDIF(AL6,AM6,"M")+1)) | AQ6: =IF(AP6="","",(DATEDIF(AO6,AP6,"M")+1)) | AT6: =IF(AS6="","",(DATEDIF(AR6,AS6,"M")+1)) | AW6: =IF(AV6="","",(DATEDIF(AU6,AV6,"M")+1)) | AZ6: =IF(AY6="","",(DATEDIF(AX6,AY6,"M")+1)) | BC6: =IF(BB6="","",(DATEDIF(BA6,BB6,"M")+1)) | BD6: =IF(G6="Tetap","",IF(BA6<>"",BA6,IF(AX6<>"",AX6,IF(AU6<>"",AU6,IF(AR6<>"",AR6,IF(AO6<>"",AO6,IF(AL6<>"",AL6,IF(AI6<>"",AI6,"")))))))) -> 46204 | BE6: =IF($AI6="","0",(DATEDIF($AI6,TODAY(),"Y"))) -> 0 | BF6: =IF($AI6="","",(DATEDIF($AI6,TODAY(),"YM"))) -> 3 | BG6: =IF($AI6="","",(DATEDIF($AI6,TODAY(),"MD"))) -> 2
A7: =A6+1 -> 5 | B7: 55005 | C7: A01005 | D7: G. Induk | E7: RAHMAD SYUKUR RITONGA | F7: Sopir | G7: =IF(AI7="","Perekrutan",IF(BE7>4,"Tetap",IF(BA7<>"","Kontrak VII",IF(AX7<>"","Kontrak VI",IF(AU7<>"","Kontrak V",IF(AR7<>"","Kontrak IV",IF(AO7<>"","Kontrak III",IF(AL7<>"","Kontrak II",IF(AI7<>"","Kontrak I",""))))))))) -> Kontrak IV | H7: =IF(G7="Tetap","",IF(BA7<>"",BB7,IF(AX7<>"",AY7,IF(AU7<>"",AV7,IF(AR7<>"",AS7,IF(AO7<>"",AP7,IF(AL7<>"",AM7,IF(AI7<>"",AJ7,"")))))))) -> 46660 | I7: - | J7: - | K7: Kab. Labuhanbatu | L7: 1210020609020004 | N7: Islam | O7: Rantauprapat | P7: 37505 | Q7: =IF(P7="","",(DATEDIF(P7,TODAY(),"Y"))) -> 24 | R7: Jl. Suka Dame Lingk. Simp. IV Padang Pasir RT / RW 000 Desa Urung Kompas Kec. Rantau Selatan Kab. Labuhanbatu Sumut | S7: L | T7: Belum Kawin | U7: - | V7: SMK | Z7: 1917230787 | AA7: 993940089116000 | AC7: Sopir Lepas | AI7: 45916 | AJ7: 46053 | AK7: =IF(AJ7="","",(DATEDIF(AI7,AJ7,"M")+1)) -> 5 | AL7: 46054 | AM7: 46173 | AN7: =IF(AM7="","",(DATEDIF(AL7,AM7,"M")+1)) -> 4 | AO7: 46174 | AP7: 46295 | AQ7: =IF(AP7="","",(DATEDIF(AO7,AP7,"M")+1)) -> 4 | AR7: 46296 | AS7: 46660 | AT7: =IF(AS7="","",(DATEDIF(AR7,AS7,"M")+1)) -> 12 | AW7: =IF(AV7="","",(DATEDIF(AU7,AV7,"M")+1)) | AZ7: =IF(AY7="","",(DATEDIF(AX7,AY7,"M")+1)) | BC7: =IF(BB7="","",(DATEDIF(BA7,BB7,"M")+1)) | BD7: =IF(G7="Tetap","",IF(BA7<>"",BA7,IF(AX7<>"",AX7,IF(AU7<>"",AU7,IF(AR7<>"",AR7,IF(AO7<>"",AO7,IF(AL7<>"",AL7,IF(AI7<>"",AI7,"")))))))) -> 46296 | BE7: =IF($AI7="","0",(DATEDIF($AI7,TODAY(),"Y"))) -> 1 | BF7: =IF($AI7="","",(DATEDIF($AI7,TODAY(),"YM"))) -> 0 | BG7: =IF($AI7="","",(DATEDIF($AI7,TODAY(),"MD"))) -> 17
A8: 1 | B8: 55007 | C8: A02001 | D8: RIAU | E8: ANGGI ARULI | F8: Plt Ka. Area Pekan Baru | G8: =IF(AI8="","Perekrutan",IF(BE8>4,"Tetap",IF(BA8<>"","Kontrak VII",IF(AX8<>"","Kontrak VI",IF(AU8<>"","Kontrak V",IF(AR8<>"","Kontrak IV",IF(AO8<>"","Kontrak III",IF(AL8<>"","Kontrak II",IF(AI8<>"","Kontrak I",""))))))))) -> Kontrak IV | H8: =IF(G8="Tetap","",IF(BA8<>"",BB8,IF(AX8<>"",AY8,IF(AU8<>"",AV8,IF(AR8<>"",AS8,IF(AO8<>"",AP8,IF(AL8<>"",AM8,IF(AI8<>"",AJ8,"")))))))) -> 46387 | I8: - | J8: 11 | K8: P. Siantar | L8: 1271200307810004 | M8: 1271040606120003 | N8: Islam | O8: Medan | P8: 29770 | Q8: =IF(P8="","",(DATEDIF(P8,TODAY(),"Y"))) -> 45 | R8: Jl. Kesehatan Gg. Cinta Mata No. 4, RT 000 / RW 000, Kelurahan Medan Tenggara, Kecamatan Medan Denai, Kota Medan | S8: L | T8: Kawin | U8: K02 | V8: S1 Ekonomi | Y8: 0853-6408-6145 | Z8: 1918046458 | AA8: 1271200307810004 | AB8: Anggiarulli1982@gmail.com | AC8: Freelance | AI8: 45659 | AJ8: 45777 | AK8: =IF(AJ8="","",(DATEDIF(AI8,AJ8,"M")+1)) -> 4 | AL8: 45778 | AM8: 45900 | AN8: =IF(AM8="","",(DATEDIF(AL8,AM8,"M")+1)) -> 4 | AO8: 45901 | AP8: 46022 | AQ8: =IF(AP8="","",(DATEDIF(AO8,AP8,"M")+1)) -> 4 | AR8: 46023 | AS8: 46387 | AT8: =IF(AS8="","",(DATEDIF(AR8,AS8,"M")+1)) -> 12 | AW8: =IF(AV8="","",(DATEDIF(AU8,AV8,"M")+1)) | AZ8: =IF(AY8="","",(DATEDIF(AX8,AY8,"M")+1)) | BC8: =IF(BB8="","",(DATEDIF(BA8,BB8,"M")+1)) | BD8: =IF(G8="Tetap","",IF(BA8<>"",BA8,IF(AX8<>"",AX8,IF(AU8<>"",AU8,IF(AR8<>"",AR8,IF(AO8<>"",AO8,IF(AL8<>"",AL8,IF(AI8<>"",AI8,"")))))))) -> 46023 | BE8: =IF($AI8="","0",(DATEDIF($AI8,TODAY(),"Y"))) -> 1 | BF8: =IF($AI8="","",(DATEDIF($AI8,TODAY(),"YM"))) -> 9 | BG8: =IF($AI8="","",(DATEDIF($AI8,TODAY(),"MD"))) -> 1
A9: =A8+1 -> 2 | B9: 55008 | C9: A02002 | D9: RIAU | E9: ADI HENRATNO | F9: Sales Executive (Dropping) | G9: =IF(AI9="","Perekrutan",IF(BE9>4,"Tetap",IF(BA9<>"","Kontrak VII",IF(AX9<>"","Kontrak VI",IF(AU9<>"","Kontrak V",IF(AR9<>"","Kontrak IV",IF(AO9<>"","Kontrak III",IF(AL9<>"","Kontrak II",IF(AI9<>"","Kontrak I",""))))))))) -> Tetap | H9: =IF(G9="Tetap","",IF(BA9<>"",BB9,IF(AX9<>"",AY9,IF(AU9<>"",AV9,IF(AR9<>"",AS9,IF(AO9<>"",AP9,IF(AL9<>"",AM9,IF(AI9<>"",AJ9,"")))))))) | I9: A | J9: 9 | K9: Kab. Labuhanbatu | L9: 1210011501870001 | M9: 1210010206110003 | N9: Islam | O9: Negeri Lama Seberang | P9: 31792 | Q9: =IF(P9="","",(DATEDIF(P9,TODAY(),"Y"))) -> 39 | R9: Jl. Balai Desa Gg. Amal, RT 000 / Rw 000, Desa Padang Bulan, Kecamatan Rantau Utara, Kabupaten Labuhanbatu | S9: L | T9: Cerai Hidup | U9: TK01 | Y9: 0853-8125-8571 | Z9: 1815077867 | AA9: 1210011501870001 | AB9: hendraa6541@gmail.com | AC9: 3 Juli - 03 Agust 2019 | AI9: 43664 | AJ9: 43848 | AK9: =IF(AJ9="","",(DATEDIF(AI9,AJ9,"M")+1)) -> 7 | AL9: 43850 | AM9: 44032 | AN9: =IF(AM9="","",(DATEDIF(AL9,AM9,"M")+1)) -> 7 | AO9: 44033 | AP9: 44763 | AQ9: =IF(AP9="","",(DATEDIF(AO9,AP9,"M")+1)) -> 25 | AR9: 44764 | AS9: 45504 | AT9: =IF(AS9="","",(DATEDIF(AR9,AS9,"M")+1)) -> 25 | AW9: =IF(AV9="","",(DATEDIF(AU9,AV9,"M")+1)) | AZ9: =IF(AY9="","",(DATEDIF(AX9,AY9,"M")+1)) | BC9: =IF(BB9="","",(DATEDIF(BA9,BB9,"M")+1)) | BD9: =IF(G9="Tetap","",IF(BA9<>"",BA9,IF(AX9<>"",AX9,IF(AU9<>"",AU9,IF(AR9<>"",AR9,IF(AO9<>"",AO9,IF(AL9<>"",AL9,IF(AI9<>"",AI9,"")))))))) | BE9: =IF($AI9="","0",(DATEDIF($AI9,TODAY(),"Y"))) -> 7 | BF9: =IF($AI9="","",(DATEDIF($AI9,TODAY(),"YM"))) -> 2 | BG9: =IF($AI9="","",(DATEDIF($AI9,TODAY(),"MD"))) -> 15
A10: =A9+1 -> 3 | B10: 55009 | C10: A02003 | D10: RIAU | E10: ANTONIUS MANULLANG | F10: Sales Executive (Dropping) | G10: =IF(AI10="","Perekrutan",IF(BE10>4,"Tetap",IF(BA10<>"","Kontrak VII",IF(AX10<>"","Kontrak VI",IF(AU10<>"","Kontrak V",IF(AR10<>"","Kontrak IV",IF(AO10<>"","Kontrak III",IF(AL10<>"","Kontrak II",IF(AI10<>"","Kontrak I",""))))))))) -> Tetap | H10: =IF(G10="Tetap","",IF(BA10<>"",BB10,IF(AX10<>"",AY10,IF(AU10<>"",AV10,IF(AR10<>"",AS10,IF(AO10<>"",AP10,IF(AL10<>"",AM10,IF(AI10<>"",AJ10,"")))))))) | I10: A | J10: 9 | K10: P.Siantar | L10: 1218051101910001 | M10: 1272072207190001 | N10: Katolik | O10: Pematang Panjang | P10: 33249 | Q10: =IF(P10="","",(DATEDIF(P10,TODAY(),"Y"))) -> 35 | R10: Jl. Viyata Yudha. Btn Blok G-1, RT 001 / RW 001. Kelurahan Bah Kapul, Kecamatan Siantar Sitalasari, Kota Pematangsiantar | S10: L | T10: Kawin | U10: K03 | Y10: 0823-6455-1666 | Z10: 834382809 | AA10: 1218051101910001 | AB10: antonius110191@gmail.com | AC10: 02 Sep - 02 Okt 2011 | AI10: 40819 | AJ10: 40911 | AK10: =IF(AJ10="","",(DATEDIF(AI10,AJ10,"M")+1)) -> 4 | AL10: 40912 | AM10: 41429 | AN10: =IF(AM10="","",(DATEDIF(AL10,AM10,"M")+1)) -> 18 | AQ10: =IF(AP10="","",(DATEDIF(AO10,AP10,"M")+1)) | AT10: =IF(AS10="","",(DATEDIF(AR10,AS10,"M")+1)) | AW10: =IF(AV10="","",(DATEDIF(AU10,AV10,"M")+1)) | AZ10: =IF(AY10="","",(DATEDIF(AX10,AY10,"M")+1)) | BC10: =IF(BB10="","",(DATEDIF(BA10,BB10,"M")+1)) | BD10: =IF(G10="Tetap","",IF(BA10<>"",BA10,IF(AX10<>"",AX10,IF(AU10<>"",AU10,IF(AR10<>"",AR10,IF(AO10<>"",AO10,IF(AL10<>"",AL10,IF(AI10<>"",AI10,"")))))))) | BE10: =IF($AI10="","0",(DATEDIF($AI10,TODAY(),"Y"))) -> 15 | BF10: =IF($AI10="","",(DATEDIF($AI10,TODAY(),"YM"))) -> 0 | BG10: =IF($AI10="","",(DATEDIF($AI10,TODAY(),"MD"))) -> 0
A11: =A10+1 -> 4 | B11: 55010 | C11: A02004 | D11: RIAU | E11: KHAIRUDDIN | F11: Sales Executive (Dropping) | G11: =IF(AI11="","Perekrutan",IF(BE11>4,"Tetap",IF(BA11<>"","Kontrak VII",IF(AX11<>"","Kontrak VI",IF(AU11<>"","Kontrak V",IF(AR11<>"","Kontrak IV",IF(AO11<>"","Kontrak III",IF(AL11<>"","Kontrak II",IF(AI11<>"","Kontrak I",""))))))))) -> Kontrak IV | H11: =IF(G11="Tetap","",IF(BA11<>"",BB11,IF(AX11<>"",AY11,IF(AU11<>"",AV11,IF(AR11<>"",AS11,IF(AO11<>"",AP11,IF(AL11<>"",AM11,IF(AI11<>"",AJ11,"")))))))) -> 46598 | I11: - | J11: 7 | K11: Kab. Rokan Hilir | L11: 1407102502830001 | M11: 1407050901200004 | N11: Islam | O11: A. Jamu | P11: 30372 | Q11: =IF(P11="","",(DATEDIF(P11,TODAY(),"Y"))) -> 43 | R11: Jl. Sisingamangaraja Raja, RT 001 / RW 010, Desa Bagan Batu Kota, Kecamatan Bagan Sinembah, Kabupaten Rokan Hilir | S11: L | T11: Cerai Hidup | U11: TK01 | Y11: 0822-1568-2435 | Z11: 1411581796 | AA11: 600036537212000 | AB11: Dennjaka5@gmail.com | AC11: Freelance | AI11: 44726 | AJ11: 44865 | AK11: =IF(AJ11="","",(DATEDIF(AI11,AJ11,"M")+1)) -> 5 | AL11: 44866 | AM11: 45230 | AN11: =IF(AM11="","",(DATEDIF(AL11,AM11,"M")+1)) -> 12 | AO11: 45231 | AP11: 45596 | AQ11: =IF(AP11="","",(DATEDIF(AO11,AP11,"M")+1)) -> 12 | AR11: 45597 | AS11: 46598 | AT11: =IF(AS11="","",(DATEDIF(AR11,AS11,"M")+1)) -> 33 | AW11: =IF(AV11="","",(DATEDIF(AU11,AV11,"M")+1)) | AZ11: =IF(AY11="","",(DATEDIF(AX11,AY11,"M")+1)) | BC11: =IF(BB11="","",(DATEDIF(BA11,BB11,"M")+1)) | BD11: =IF(G11="Tetap","",IF(BA11<>"",BA11,IF(AX11<>"",AX11,IF(AU11<>"",AU11,IF(AR11<>"",AR11,IF(AO11<>"",AO11,IF(AL11<>"",AL11,IF(AI11<>"",AI11,"")))))))) -> 45597 | BE11: =IF($AI11="","0",(DATEDIF($AI11,TODAY(),"Y"))) -> 4 | BF11: =IF($AI11="","",(DATEDIF($AI11,TODAY(),"YM"))) -> 3 | BG11: =IF($AI11="","",(DATEDIF($AI11,TODAY(),"MD"))) -> 19
A12: =A11+1 -> 5 | B12: 55011 | C12: A02005 | D12: RIAU | E12: SYAMSUL BAHRI NASUTION | F12: Sopir | G12: =IF(AI12="","Perekrutan",IF(BE12>4,"Tetap",IF(BA12<>"","Kontrak VII",IF(AX12<>"","Kontrak VI",IF(AU12<>"","Kontrak V",IF(AR12<>"","Kontrak IV",IF(AO12<>"","Kontrak III",IF(AL12<>"","Kontrak II",IF(AI12<>"","Kontrak I",""))))))))) -> Kontrak I | H12: =IF(G12="Tetap","",IF(BA12<>"",BB12,IF(AX12<>"",AY12,IF(AU12<>"",AV12,IF(AR12<>"",AS12,IF(AO12<>"",AP12,IF(AL12<>"",AM12,IF(AI12<>"",AJ12,"")))))))) -> 46356 | I12: A | J12: - | K12: Kota Pekanbaru | L12: 1210020908800006 | M12: 1407051112170008 | N12: Islam | O12: Labuhan Bilik | P12: 29442 | Q12: =IF(P12="","",(DATEDIF(P12,TODAY(),"Y"))) -> 46 | R12: Jl. Mawar, RT 001 / RW 002, Kelurahan Bhayangkara Jaya, Kecamatan Bagan Sinembah, Kabupaten Rokan Hilir | S12: L | T12: Kawin | U12: K02 | V12: SMK Teknik Permesinan | Y12: 0823-8469-4377 | Z12: 2055837542 | AA12: 138966478212000 | AB12: samsulbahrinstbahri@gmail.com | AC12: 29 Apr - 25 Mei 2026 | AD12: 26 Mei - 22 Jun 2026 | AE12: 23 Jun - 15 Juli 2026 | AI12: 46220 | AJ12: 46356 | AK12: =IF(AJ12="","",(DATEDIF(AI12,AJ12,"M")+1)) -> 5 | AN12: =IF(AM12="","",(DATEDIF(AL12,AM12,"M")+1)) | AQ12: =IF(AP12="","",(DATEDIF(AO12,AP12,"M")+1)) | AT12: =IF(AS12="","",(DATEDIF(AR12,AS12,"M")+1)) | AW12: =IF(AV12="","",(DATEDIF(AU12,AV12,"M")+1)) | AZ12: =IF(AY12="","",(DATEDIF(AX12,AY12,"M")+1)) | BC12: =IF(BB12="","",(DATEDIF(BA12,BB12,"M")+1)) | BD12: =IF(G12="Tetap","",IF(BA12<>"",BA12,IF(AX12<>"",AX12,IF(AU12<>"",AU12,IF(AR12<>"",AR12,IF(AO12<>"",AO12,IF(AL12<>"",AL12,IF(AI12<>"",AI12,"")))))))) -> 46220 | BE12: =IF($AI12="","0",(DATEDIF($AI12,TODAY(),"Y"))) -> 0 | BF12: =IF($AI12="","",(DATEDIF($AI12,TODAY(),"YM"))) -> 2 | BG12: =IF($AI12="","",(DATEDIF($AI12,TODAY(),"MD"))) -> 16
A13: =A12+1 -> 6 | B13: 55012 | C13: A02006 | D13: RIAU | E13: IRAWAN SYAHPUTRA | F13: Sopir | G13: =IF(AI13="","Perekrutan",IF(BE13>4,"Tetap",IF(BA13<>"","Kontrak VII",IF(AX13<>"","Kontrak VI",IF(AU13<>"","Kontrak V",IF(AR13<>"","Kontrak IV",IF(AO13<>"","Kontrak III",IF(AL13<>"","Kontrak II",IF(AI13<>"","Kontrak I",""))))))))) -> Kontrak I | H13: =IF(G13="Tetap","",IF(BA13<>"",BB13,IF(AX13<>"",AY13,IF(AU13<>"",AV13,IF(AR13<>"",AS13,IF(AO13<>"",AP13,IF(AL13<>"",AM13,IF(AI13<>"",AJ13,"")))))))) -> 46387 | I13: A | J13: - | K13: Kota Pekanbaru | L13: 1405112303730000 | M13: 1405112504120013 | N13: Islam | O13: B. Betsy | P13: 26746 | Q13: =IF(P13="","",(DATEDIF(P13,TODAY(),"Y"))) -> 53 | R13: Dusun Kampung Tengah, RT 003 / RW 002, Desa Muda Setia, Kecamatan Bandar Sei Kijang, Kabupaten Pelalawan | S13: L | T13: Kawin | U13: K02 | V13: SMK | Y13: 0882-7122-6022 | Z13: 2078634217 | AB13: iwanpku734@gmail.com | AC13: 02 - 26 Juni 2026 | AD13: 27 Juni - 21 Juli 2026 | AE13: 22 Juli - 13 Agust 2026 | AI13: 46249 | AJ13: 46387 | AK13: =IF(AJ13="","",(DATEDIF(AI13,AJ13,"M")+1)) -> 5 | AQ13: =IF(AP13="","",(DATEDIF(AO13,AP13,"M")+1)) | AT13: =IF(AS13="","",(DATEDIF(AR13,AS13,"M")+1)) | AZ13: =IF(AY13="","",(DATEDIF(AX13,AY13,"M")+1)) | BC13: =IF(BB13="","",(DATEDIF(BA13,BB13,"M")+1)) | BD13: =IF(G13="Tetap","",IF(BA13<>"",BA13,IF(AX13<>"",AX13,IF(AU13<>"",AU13,IF(AR13<>"",AR13,IF(AO13<>"",AO13,IF(AL13<>"",AL13,IF(AI13<>"",AI13,"")))))))) -> 46249 | BE13: =IF($AI13="","0",(DATEDIF($AI13,TODAY(),"Y"))) -> 0 | BF13: =IF($AI13="","",(DATEDIF($AI13,TODAY(),"YM"))) -> 1 | BG13: =IF($AI13="","",(DATEDIF($AI13,TODAY(),"MD"))) -> 18
A14: 1 | B14: 55013 | C14: A03001 | D14: PS2SD | E14: ERWIN | F14: Ka. Area (Executive) | G14: =IF(AI14="","Perekrutan",IF(BE14>4,"Tetap",IF(BA14<>"","Kontrak VII",IF(AX14<>"","Kontrak VI",IF(AU14<>"","Kontrak V",IF(AR14<>"","Kontrak IV",IF(AO14<>"","Kontrak III",IF(AL14<>"","Kontrak II",IF(AI14<>"","Kontrak I",""))))))))) -> Tetap | H14: =IF(G14="Tetap","",IF(BA14<>"",BB14,IF(AX14<>"",AY14,IF(AU14<>"",AV14,IF(AR14<>"",AS14,IF(AO14<>"",AP14,IF(AL14<>"",AM14,IF(AI14<>"",AJ14,"")))))))) | K14: P.Siantar | L14: 1272061701740002 | M14: 1271202712170012 | N14: Islam | O14: Bandung | P14: 27046 | Q14: =IF(P14="","",(DATEDIF(P14,TODAY(),"Y"))) -> 52 | R14: Jl. Kapten Mukthar Basri RT 000 / RW 0000, Kelurahan Glugur Darat II, Kecamatan Medan Timur, Kota Medan | S14: L | T14: Kawin | U14: K02 | Y14: 0812-7614-2234 | Z14: 155390231 | AA14: 810096552117000 | AB14: erwin17011974@gmail.com | AI14: 36017 | AK14: =IF(AJ14="","",(DATEDIF(AI14,AJ14,"M")+1)) | AN14: =IF(AM14="","",(DATEDIF(AL14,AM14,"M")+1)) | AQ14: =IF(AP14="","",(DATEDIF(AO14,AP14,"M")+1)) | AT14: =IF(AS14="","",(DATEDIF(AR14,AS14,"M")+1)) | AW14: =IF(AV14="","",(DATEDIF(AU14,AV14,"M")+1)) | AZ14: =IF(AY14="","",(DATEDIF(AX14,AY14,"M")+1)) | BC14: =IF(BB14="","",(DATEDIF(BA14,BB14,"M")+1)) | BD14: =IF(G14="Tetap","",IF(BA14<>"",BA14,IF(AX14<>"",AX14,IF(AU14<>"",AU14,IF(AR14<>"",AR14,IF(AO14<>"",AO14,IF(AL14<>"",AL14,IF(AI14<>"",AI14,"")))))))) | BE14: =IF($AI14="","0",(DATEDIF($AI14,TODAY(),"Y"))) -> 28 | BF14: =IF($AI14="","",(DATEDIF($AI14,TODAY(),"YM"))) -> 1 | BG14: =IF($AI14="","",(DATEDIF($AI14,TODAY(),"MD"))) -> 23
A15: =A14+1 -> 2 | B15: 55014 | C15: A03002 | D15: PS2SD | E15: MASIH ANJAYA | F15: Sales Executive (Dropping) | G15: =IF(AI15="","Perekrutan",IF(BE15>4,"Tetap",IF(BA15<>"","Kontrak VII",IF(AX15<>"","Kontrak VI",IF(AU15<>"","Kontrak V",IF(AR15<>"","Kontrak IV",IF(AO15<>"","Kontrak III",IF(AL15<>"","Kontrak II",IF(AI15<>"","Kontrak I",""))))))))) -> Tetap | H15: =IF(G15="Tetap","",IF(BA15<>"",BB15,IF(AX15<>"",AY15,IF(AU15<>"",AV15,IF(AR15<>"",AS15,IF(AO15<>"",AP15,IF(AL15<>"",AM15,IF(AI15<>"",AJ15,"")))))))) | I15: B | J15: 11 | K15: P.Siantar | L15: 1208111410770001 | M15: 1208112404080123 | N15: Islam | O15: Balimbingan | P15: 28412 | Q15: =IF(P15="","",(DATEDIF(P15,TODAY(),"Y"))) -> 48 | R15: Hutan Rintis IX, RT 000 / RW 000, Kelurahan Balimbingan, Kecamatan Tanah Jawa, Kabupaten Simalungun | S15: L | T15: Kawin | U15: K02 | Y15: 0852-9641-1153 | Z15: 834192240 | AA15: 493619225117000 | AB15: dimasseto77153@gmail.com | AI15: 38599 | AK15: =IF(AJ15="","",(DATEDIF(AI15,AJ15,"M")+1)) | AN15: =IF(AM15="","",(DATEDIF(AL15,AM15,"M")+1)) | AQ15: =IF(AP15="","",(DATEDIF(AO15,AP15,"M")+1)) | AT15: =IF(AS15="","",(DATEDIF(AR15,AS15,"M")+1)) | AW15: =IF(AV15="","",(DATEDIF(AU15,AV15,"M")+1)) | AZ15: =IF(AY15="","",(DATEDIF(AX15,AY15,"M")+1)) | BC15: =IF(BB15="","",(DATEDIF(BA15,BB15,"M")+1)) | BD15: =IF(G15="Tetap","",IF(BA15<>"",BA15,IF(AX15<>"",AX15,IF(AU15<>"",AU15,IF(AR15<>"",AR15,IF(AO15<>"",AO15,IF(AL15<>"",AL15,IF(AI15<>"",AI15,"")))))))) | BE15: =IF($AI15="","0",(DATEDIF($AI15,TODAY(),"Y"))) -> 21 | BF15: =IF($AI15="","",(DATEDIF($AI15,TODAY(),"YM"))) -> 0 | BG15: =IF($AI15="","",(DATEDIF($AI15,TODAY(),"MD"))) -> 29
A16: =A15+1 -> 3 | B16: 55015 | C16: A03003 | D16: PS2SD | E16: SEGER | F16: Sales Executive (Dropping) | G16: =IF(AI16="","Perekrutan",IF(BE16>4,"Tetap",IF(BA16<>"","Kontrak VII",IF(AX16<>"","Kontrak VI",IF(AU16<>"","Kontrak V",IF(AR16<>"","Kontrak IV",IF(AO16<>"","Kontrak III",IF(AL16<>"","Kontrak II",IF(AI16<>"","Kontrak I",""))))))))) -> Tetap | H16: =IF(G16="Tetap","",IF(BA16<>"",BB16,IF(AX16<>"",AY16,IF(AU16<>"",AV16,IF(AR16<>"",AS16,IF(AO16<>"",AP16,IF(AL16<>"",AM16,IF(AI16<>"",AJ16,"")))))))) | I16: A | J16: 9 | K16: P.Siantar | L16: 1272070809740005 | M16: 1272070602080135 | N16: Islam | O16: P. Siantar | P16: 27280 | Q16: =IF(P16="","",(DATEDIF(P16,TODAY(),"Y"))) -> 52 | R16: Jl. Sibatu Batu Komplek Mesjid RT 010 / RW 004, Kelurahan Bah Kapul, Kecamatan Siantar Sitalasari, Kota Pematangsiantar | S16: L | T16: Kawin | U16: K03 | Y16: 0853-6162-6153 | Z16: 834351166 | AA16: 971488846117000 | AB16: seger8520@gmail.com | AC16: 04 Des 2010 - 05 Mar 2011 | AI16: 40609 | AJ16: 40700 | AK16: =IF(AJ16="","",(DATEDIF(AI16,AJ16,"M")+1)) -> 3 | AL16: 40701 | AM16: 41066 | AN16: =IF(AM16="","",(DATEDIF(AL16,AM16,"M")+1)) -> 12 | AQ16: =IF(AP16="","",(DATEDIF(AO16,AP16,"M")+1)) | AT16: =IF(AS16="","",(DATEDIF(AR16,AS16,"M")+1)) | AW16: =IF(AV16="","",(DATEDIF(AU16,AV16,"M")+1)) | AZ16: =IF(AY16="","",(DATEDIF(AX16,AY16,"M")+1)) | BC16: =IF(BB16="","",(DATEDIF(BA16,BB16,"M")+1)) | BD16: =IF(G16="Tetap","",IF(BA16<>"",BA16,IF(AX16<>"",AX16,IF(AU16<>"",AU16,IF(AR16<>"",AR16,IF(AO16<>"",AO16,IF(AL16<>"",AL16,IF(AI16<>"",AI16,"")))))))) | BE16: =IF($AI16="","0",(DATEDIF($AI16,TODAY(),"Y"))) -> 15 | BF16: =IF($AI16="","",(DATEDIF($AI16,TODAY(),"YM"))) -> 6 | BG16: =IF($AI16="","",(DATEDIF($AI16,TODAY(),"MD"))) -> 26
A17: =A16+1 -> 4 | B17: 55016 | C17: A03004 | D17: PS2SD | E17: HERMANSYAH SIREGAR | F17: Sales Executive (Dropping) | G17: =IF(AI17="","Perekrutan",IF(BE17>4,"Tetap",IF(BA17<>"","Kontrak VII",IF(AX17<>"","Kontrak VI",IF(AU17<>"","Kontrak V",IF(AR17<>"","Kontrak IV",IF(AO17<>"","Kontrak III",IF(AL17<>"","Kontrak II",IF(AI17<>"","Kontrak I",""))))))))) -> Tetap | H17: =IF(G17="Tetap","",IF(BA17<>"",BB17,IF(AX17<>"",AY17,IF(AU17<>"",AV17,IF(AR17<>"",AS17,IF(AO17<>"",AP17,IF(AL17<>"",AM17,IF(AI17<>"",AJ17,"")))))))) | I17: A | J17: 9 | K17: P.Siantar | L17: 1272031705790005 | M17: 1272031404080007 | N17: Islam | O17: P. Siantar | P17: 28992 | Q17: =IF(P17="","",(DATEDIF(P17,TODAY(),"Y"))) -> 47 | R17: Jl. Singosari Gg. Demak, RT 001 / RW 001, Keluarahan Martoba,Kecamatan Siantar Utara, Kota Pematangsiantar | S17: L | T17: Kawin | U17: K02 | Y17: 0823-6209-5007 | Z17: 834344375 | AA17: 843540642117000 | AB17: hermansyahsiregar302@gmail.com | AI17: 38364 | AK17: =IF(AJ17="","",(DATEDIF(AI17,AJ17,"M")+1)) | AN17: =IF(AM17="","",(DATEDIF(AL17,AM17,"M")+1)) | AQ17: =IF(AP17="","",(DATEDIF(AO17,AP17,"M")+1)) | AT17: =IF(AS17="","",(DATEDIF(AR17,AS17,"M")+1)) | AW17: =IF(AV17="","",(DATEDIF(AU17,AV17,"M")+1)) | AZ17: =IF(AY17="","",(DATEDIF(AX17,AY17,"M")+1)) | BC17: =IF(BB17="","",(DATEDIF(BA17,BB17,"M")+1)) | BD17: =IF(G17="Tetap","",IF(BA17<>"",BA17,IF(AX17<>"",AX17,IF(AU17<>"",AU17,IF(AR17<>"",AR17,IF(AO17<>"",AO17,IF(AL17<>"",AL17,IF(AI17<>"",AI17,"")))))))) | BE17: =IF($AI17="","0",(DATEDIF($AI17,TODAY(),"Y"))) -> 21 | BF17: =IF($AI17="","",(DATEDIF($AI17,TODAY(),"YM"))) -> 8 | BG17: =IF($AI17="","",(DATEDIF($AI17,TODAY(),"MD"))) -> 21
A18: =A17+1 -> 5 | B18: 55017 | C18: A03005 | D18: PS2SD | E18: NURAINI LARADATA SILALAHI | F18: Sales Executive (Dropping) | G18: =IF(AI18="","Perekrutan",IF(BE18>4,"Tetap",IF(BA18<>"","Kontrak VII",IF(AX18<>"","Kontrak VI",IF(AU18<>"","Kontrak V",IF(AR18<>"","Kontrak IV",IF(AO18<>"","Kontrak III",IF(AL18<>"","Kontrak II",IF(AI18<>"","Kontrak I",""))))))))) -> Kontrak IV | H18: =IF(G18="Tetap","",IF(BA18<>"",BB18,IF(AX18<>"",AY18,IF(AU18<>"",AV18,IF(AR18<>"",AS18,IF(AO18<>"",AP18,IF(AL18<>"",AM18,IF(AI18<>"",AJ18,"")))))))) -> 46326 | I18: A | J18: 9 | K18: Kab. Dairi | L18: 1211015708000005 | M18: 1211153005170005 | N18: Islam | O18: Sidikalang | P18: 36757 | Q18: =IF(P18="","",(DATEDIF(P18,TODAY(),"Y"))) -> 26 | R18: Jl. Sidikalang Medan Panji Bako, RT - / RW -, Desa Sitinjo II, Kecamatan Sitinjo, Kabupaten Dairi | S18: L | T18: Belum Kawin | U18: TK0 | V18: SMA | Y18: 0821-2274-0940 | Z18: 1513150286 | AA18: 1211015708000005 | AB18: datasilalahi22@gmail.com | AC18: Freelance | AI18: 45576 | AJ18: 45716 | AK18: =IF(AJ18="","",(DATEDIF(AI18,AJ18,"M")+1)) -> 5 | AL18: 45717 | AM18: 45838 | AN18: =IF(AM18="","",(DATEDIF(AL18,AM18,"M")+1)) -> 4 | AO18: 45839 | AP18: 45961 | AQ18: =IF(AP18="","",(DATEDIF(AO18,AP18,"M")+1)) -> 4 | AR18: 45962 | AS18: 46326 | AT18: =IF(AS18="","",(DATEDIF(AR18,AS18,"M")+1)) -> 12 | AW18: =IF(AV18="","",(DATEDIF(AU18,AV18,"M")+1)) | AZ18: =IF(AY18="","",(DATEDIF(AX18,AY18,"M")+1)) | BC18: =IF(BB18="","",(DATEDIF(BA18,BB18,"M")+1)) | BD18: =IF(G18="Tetap","",IF(BA18<>"",BA18,IF(AX18<>"",AX18,IF(AU18<>"",AU18,IF(AR18<>"",AR18,IF(AO18<>"",AO18,IF(AL18<>"",AL18,IF(AI18<>"",AI18,"")))))))) -> 45962 | BE18: =IF($AI18="","0",(DATEDIF($AI18,TODAY(),"Y"))) -> 1 | BF18: =IF($AI18="","",(DATEDIF($AI18,TODAY(),"YM"))) -> 11 | BG18: =IF($AI18="","",(DATEDIF($AI18,TODAY(),"MD"))) -> 22
A19: =A18+1 -> 6 | B19: 55018 | C19: A03006 | D19: PS2SD | E19: SRI WAHYUNI | F19: Administrasi Penjualan & Gudang (Kecil) Area | G19: =IF(AI19="","Perekrutan",IF(BE19>4,"Tetap",IF(BA19<>"","Kontrak VII",IF(AX19<>"","Kontrak VI",IF(AU19<>"","Kontrak V",IF(AR19<>"","Kontrak IV",IF(AO19<>"","Kontrak III",IF(AL19<>"","Kontrak II",IF(AI19<>"","Kontrak I",""))))))))) -> Tetap | H19: =IF(G19="Tetap","",IF(BA19<>"",BB19,IF(AX19<>"",AY19,IF(AU19<>"",AV19,IF(AR19<>"",AS19,IF(AO19<>"",AP19,IF(AL19<>"",AM19,IF(AI19<>"",AJ19,"")))))))) | I19: C | J19: 6 | K19: P.Siantar | L19: 1208176810880001 | M19: 1208171111150003 | N19: Islam | O19: Malopot | P19: 32424 | Q19: =IF(P19="","",(DATEDIF(P19,TODAY(),"Y"))) -> 37 | R19: Huta Malopot, RT 000 / RW 000, Kelurahan Silenduk, Kecamatan Dolok Batu Nanggar, Kabupaten Simalungun | S19: P | T19: Kawin | U19: K02 | Y19: 0852-7530-1535 | Z19: 817291195 | AA19: 798005666117000 | AB19: sriwahyuniutomo@yahoo.com | AC19: 05 Mei – 05 Agust 2009 | AI19: 38935 | AK19: =IF(AJ19="","",(DATEDIF(AI19,AJ19,"M")+1)) | AN19: =IF(AM19="","",(DATEDIF(AL19,AM19,"M")+1)) | AQ19: =IF(AP19="","",(DATEDIF(AO19,AP19,"M")+1)) | AT19: =IF(AS19="","",(DATEDIF(AR19,AS19,"M")+1)) | AW19: =IF(AV19="","",(DATEDIF(AU19,AV19,"M")+1)) | AZ19: =IF(AY19="","",(DATEDIF(AX19,AY19,"M")+1)) | BC19: =IF(BB19="","",(DATEDIF(BA19,BB19,"M")+1)) | BD19: =IF(G19="Tetap","",IF(BA19<>"",BA19,IF(AX19<>"",AX19,IF(AU19<>"",AU19,IF(AR19<>"",AR19,IF(AO19<>"",AO19,IF(AL19<>"",AL19,IF(AI19<>"",AI19,"")))))))) | BE19: =IF($AI19="","0",(DATEDIF($AI19,TODAY(),"Y"))) -> 20 | BF19: =IF($AI19="","",(DATEDIF($AI19,TODAY(),"YM"))) -> 1 | BG19: =IF($AI19="","",(DATEDIF($AI19,TODAY(),"MD"))) -> 27
A20: =A19+1 -> 7 | B20: 55019 | C20: A03007 | D20: PS2SD | E20: ANTONI | F20: Sales | G20: =IF(AI20="","Perekrutan",IF(BE20>4,"Tetap",IF(BA20<>"","Kontrak VII",IF(AX20<>"","Kontrak VI",IF(AU20<>"","Kontrak V",IF(AR20<>"","Kontrak IV",IF(AO20<>"","Kontrak III",IF(AL20<>"","Kontrak II",IF(AI20<>"","Kontrak I",""))))))))) -> Tetap | H20: =IF(G20="Tetap","",IF(BA20<>"",BB20,IF(AX20<>"",AY20,IF(AU20<>"",AV20,IF(AR20<>"",AS20,IF(AO20<>"",AP20,IF(AL20<>"",AM20,IF(AI20<>"",AJ20,"")))))))) | I20: B | J20: 5 | K20: P.Siantar | L20: 1208013108820002 | M20: 1208012503110002 | N20: Islam | O20: P. Siantar | P20: 30194 | Q20: =IF(P20="","",(DATEDIF(P20,TODAY(),"Y"))) -> 44 | R20: Jln. Naga Bonar, RT 000 / RW 000, Kelurahan Siantar Estate, Kecamatan Siantar, Kabupaten Simalungun | S20: L | T20: Kawin | U20: K03 | Y20: 0812-6378-1909 | Z20: 248976739 | AA20: 974184202117000 | AB20: tonik1246@gmail.com | AC20: 06 Sep 11 - 30 Apr 2012 | AI20: 41030 | AJ20: 41122 | AK20: =IF(AJ20="","",(DATEDIF(AI20,AJ20,"M")+1)) -> 4 | AL20: 41123 | AM20: 41488 | AN20: =IF(AM20="","",(DATEDIF(AL20,AM20,"M")+1)) -> 13 | AQ20: =IF(AP20="","",(DATEDIF(AO20,AP20,"M")+1)) | AT20: =IF(AS20="","",(DATEDIF(AR20,AS20,"M")+1)) | AW20: =IF(AV20="","",(DATEDIF(AU20,AV20,"M")+1)) | AZ20: =IF(AY20="","",(DATEDIF(AX20,AY20,"M")+1)) | BC20: =IF(BB20="","",(DATEDIF(BA20,BB20,"M")+1)) | BD20: =IF(G20="Tetap","",IF(BA20<>"",BA20,IF(AX20<>"",AX20,IF(AU20<>"",AU20,IF(AR20<>"",AR20,IF(AO20<>"",AO20,IF(AL20<>"",AL20,IF(AI20<>"",AI20,"")))))))) | BE20: =IF($AI20="","0",(DATEDIF($AI20,TODAY(),"Y"))) -> 14 | BF20: =IF($AI20="","",(DATEDIF($AI20,TODAY(),"YM"))) -> 5 | BG20: =IF($AI20="","",(DATEDIF($AI20,TODAY(),"MD"))) -> 2
A21: =A20+1 -> 8 | B21: 55020 | C21: A03008 | D21: PS2SD | E21: YOPPI PRAYUGO | F21: Sales | G21: =IF(AI21="","Perekrutan",IF(BE21>4,"Tetap",IF(BA21<>"","Kontrak VII",IF(AX21<>"","Kontrak VI",IF(AU21<>"","Kontrak V",IF(AR21<>"","Kontrak IV",IF(AO21<>"","Kontrak III",IF(AL21<>"","Kontrak II",IF(AI21<>"","Kontrak I",""))))))))) -> Kontrak IV | H21: =IF(G21="Tetap","",IF(BA21<>"",BB21,IF(AX21<>"",AY21,IF(AU21<>"",AV21,IF(AR21<>"",AS21,IF(AO21<>"",AP21,IF(AL21<>"",AM21,IF(AI21<>"",AJ21,"")))))))) -> 46630 | I21: A | J21: 3 | K21: P. Siantar | L21: 1208012310830003 | M21: 1272021511110006 | N21: Islam | O21: P. Siantar | P21: 30612 | Q21: =IF(P21="","",(DATEDIF(P21,TODAY(),"Y"))) -> 42 | R21: Jl. Batalion, RT 004 / RW 008, Kelurahan Bantan, Kecamatan Siantar Barat, Kota Pematangsiantar | S21: L | T21: Kawin | U21: K04 | V21: SMK | Y21: 0857-6340-1172 | Z21: 1941771534 | AA21: 261398671117000 | AB21: yoppyprayugo824@gmail.com | AC21: Sales Lepas | AI21: 45901 | AJ21: 46022 | AK21: =IF(AJ21="","",(DATEDIF(AI21,AJ21,"M")+1)) -> 4 | AL21: 46023 | AM21: 46142 | AN21: =IF(AM21="","",(DATEDIF(AL21,AM21,"M")+1)) -> 4 | AO21: 46143 | AP21: 46265 | AQ21: =IF(AP21="","",(DATEDIF(AO21,AP21,"M")+1)) -> 4 | AR21: 46266 | AS21: 46630 | AT21: =IF(AS21="","",(DATEDIF(AR21,AS21,"M")+1)) -> 12 | AW21: =IF(AV21="","",(DATEDIF(AU21,AV21,"M")+1)) | AZ21: =IF(AY21="","",(DATEDIF(AX21,AY21,"M")+1)) | BC21: =IF(BB21="","",(DATEDIF(BA21,BB21,"M")+1)) | BD21: =IF(G21="Tetap","",IF(BA21<>"",BA21,IF(AX21<>"",AX21,IF(AU21<>"",AU21,IF(AR21<>"",AR21,IF(AO21<>"",AO21,IF(AL21<>"",AL21,IF(AI21<>"",AI21,"")))))))) -> 46266 | BE21: =IF($AI21="","0",(DATEDIF($AI21,TODAY(),"Y"))) -> 1 | BF21: =IF($AI21="","",(DATEDIF($AI21,TODAY(),"YM"))) -> 1 | BG21: =IF($AI21="","",(DATEDIF($AI21,TODAY(),"MD"))) -> 2
A22: =A21+1 -> 9 | B22: 55021 | C22: A03009 | D22: PS2SD | E22: ARDIANSYAH | F22: Sales | G22: =IF(AI22="","Perekrutan",IF(BE22>4,"Tetap",IF(BA22<>"","Kontrak VII",IF(AX22<>"","Kontrak VI",IF(AU22<>"","Kontrak V",IF(AR22<>"","Kontrak IV",IF(AO22<>"","Kontrak III",IF(AL22<>"","Kontrak II",IF(AI22<>"","Kontrak I",""))))))))) -> Tetap | H22: =IF(G22="Tetap","",IF(BA22<>"",BB22,IF(AX22<>"",AY22,IF(AU22<>"",AV22,IF(AR22<>"",AS22,IF(AO22<>"",AP22,IF(AL22<>"",AM22,IF(AI22<>"",AJ22,"")))))))) | I22: A | J22: 3 | K22: P.Siantar | L22: 1272071512810003 | M22: 1272070509071219 | N22: Islam | O22: Blok III | P22: 29935 | Q22: =IF(P22="","",(DATEDIF(P22,TODAY(),"Y"))) -> 44 | R22: Jl. Sibatu-Batu Blok.III, RT 011 / RW 004, Desa Bah Kapul, Kecamatan Siantar Sitalasari, Kota Pematangsiantar | S22: L | T22: Kawin | U22: K03 | Y22: 0813-7568-2594 | Z22: 834361038 | AA22: 082363516117000 | AB22: ardiankangebet@gmail.com | AC22: 25 Jul 11 - 31 Jan 2012 | AI22: 40940 | AJ22: 41030 | AK22: =IF(AJ22="","",(DATEDIF(AI22,AJ22,"M")+1)) -> 4 | AL22: 41031 | AM22: 41396 | AN22: =IF(AM22="","",(DATEDIF(AL22,AM22,"M")+1)) -> 13 | AQ22: =IF(AP22="","",(DATEDIF(AO22,AP22,"M")+1)) | AT22: =IF(AS22="","",(DATEDIF(AR22,AS22,"M")+1)) | AW22: =IF(AV22="","",(DATEDIF(AU22,AV22,"M")+1)) | AZ22: =IF(AY22="","",(DATEDIF(AX22,AY22,"M")+1)) | BC22: =IF(BB22="","",(DATEDIF(BA22,BB22,"M")+1)) | BD22: =IF(G22="Tetap","",IF(BA22<>"",BA22,IF(AX22<>"",AX22,IF(AU22<>"",AU22,IF(AR22<>"",AR22,IF(AO22<>"",AO22,IF(AL22<>"",AL22,IF(AI22<>"",AI22,"")))))))) | BE22: =IF($AI22="","0",(DATEDIF($AI22,TODAY(),"Y"))) -> 14 | BF22: =IF($AI22="","",(DATEDIF($AI22,TODAY(),"YM"))) -> 8 | BG22: =IF($AI22="","",(DATEDIF($AI22,TODAY(),"MD"))) -> 2
A23: =A22+1 -> 10 | B23: 55022 | C23: A03010 | D23: PS2SD | E23: RAYHAN ERLIA FAHRIZA | F23: Sales | G23: =IF(AI23="","Perekrutan",IF(BE23>4,"Tetap",IF(BA23<>"","Kontrak VII",IF(AX23<>"","Kontrak VI",IF(AU23<>"","Kontrak V",IF(AR23<>"","Kontrak IV",IF(AO23<>"","Kontrak III",IF(AL23<>"","Kontrak II",IF(AI23<>"","Kontrak I",""))))))))) -> Kontrak IV | H23: =IF(G23="Tetap","",IF(BA23<>"",BB23,IF(AX23<>"",AY23,IF(AU23<>"",AV23,IF(AR23<>"",AS23,IF(AO23<>"",AP23,IF(AL23<>"",AM23,IF(AI23<>"",AJ23,"")))))))) -> 46599 | I23: A | J23: 3 | K23: Simalungun Atas | L23: 1272060108020005 | M23: 1271202712170012 | N23: Islam | O23: Pematangsiantar | P23: 37469 | Q23: =IF(P23="","",(DATEDIF(P23,TODAY(),"Y"))) -> 24 | R23: Jl. Kapten Mukthar Basri, RT 000 / RW 000, Kelurahan Glugur Darat II, Kecamatan Medan Timur, Kota Medan | S23: L | T23: Belum Kawin | V23: SMK | Y23: 0822-6788-0787 | Z23: 1822874207 | AA23: 1272060108020005 | AB23: rayhanerlia7@gmail.com | AC23: Freelance | AI23: 45871 | AJ23: 45991 | AK23: =IF(AJ23="","",(DATEDIF(AI23,AJ23,"M")+1)) -> 4 | AL23: 45992 | AM23: 46112 | AN23: =IF(AM23="","",(DATEDIF(AL23,AM23,"M")+1)) -> 4 | AO23: 46113 | AP23: 46234 | AQ23: =IF(AP23="","",(DATEDIF(AO23,AP23,"M")+1)) -> 4 | AR23: 46235 | AS23: 46599 | AT23: =IF(AS23="","",(DATEDIF(AR23,AS23,"M")+1)) -> 12 | AW23: =IF(AV23="","",(DATEDIF(AU23,AV23,"M")+1)) | AZ23: =IF(AY23="","",(DATEDIF(AX23,AY23,"M")+1)) | BC23: =IF(BB23="","",(DATEDIF(BA23,BB23,"M")+1)) | BD23: =IF(G23="Tetap","",IF(BA23<>"",BA23,IF(AX23<>"",AX23,IF(AU23<>"",AU23,IF(AR23<>"",AR23,IF(AO23<>"",AO23,IF(AL23<>"",AL23,IF(AI23<>"",AI23,"")))))))) -> 46235 | BE23: =IF($AI23="","0",(DATEDIF($AI23,TODAY(),"Y"))) -> 1 | BF23: =IF($AI23="","",(DATEDIF($AI23,TODAY(),"YM"))) -> 2 | BG23: =IF($AI23="","",(DATEDIF($AI23,TODAY(),"MD"))) -> 1
A24: =A23+1 -> 11 | B24: 55023 | C24: A03011 | D24: PS2SD | E24: IQHBAL DWI PANGGA | F24: Sales | G24: =IF(AI24="","Perekrutan",IF(BE24>4,"Tetap",IF(BA24<>"","Kontrak VII",IF(AX24<>"","Kontrak VI",IF(AU24<>"","Kontrak V",IF(AR24<>"","Kontrak IV",IF(AO24<>"","Kontrak III",IF(AL24<>"","Kontrak II",IF(AI24<>"","Kontrak I",""))))))))) -> Kontrak IV | H24: =IF(G24="Tetap","",IF(BA24<>"",BB24,IF(AX24<>"",AY24,IF(AU24<>"",AV24,IF(AR24<>"",AS24,IF(AO24<>"",AP24,IF(AL24<>"",AM24,IF(AI24<>"",AJ24,"")))))))) -> 46599 | I24: A | J24: 3 | K24: Simalungun Atas | L24: 1208221310040001 | M24: 1208222904080628 | N24: Islam | O24: P. Bahapal | P24: 38273 | Q24: =IF(P24="","",(DATEDIF(P24,TODAY(),"Y"))) -> 21 | R24: Pekan Bahapal, RT 000 / RW 000, Desa Naga Jaya I, Kecamatan Bandar Huluan, Kabupaten Simalungun | S24: L | T24: Belum Kawin | V24: SMK | Y24: 0813-7024-7445 | Z24: 1926734046 | AA24: 1208221310040001 | AB24: iqhbaldwipangga73@gmail.com | AC24: Freelance | AI24: 45872 | AJ24: 45992 | AK24: =IF(AJ24="","",(DATEDIF(AI24,AJ24,"M")+1)) -> 4 | AL24: 45992 | AM24: 46112 | AN24: =IF(AM24="","",(DATEDIF(AL24,AM24,"M")+1)) -> 4 | AO24: 46113 | AP24: 46234 | AQ24: =IF(AP24="","",(DATEDIF(AO24,AP24,"M")+1)) -> 4 | AR24: 46235 | AS24: 46599 | AT24: =IF(AS24="","",(DATEDIF(AR24,AS24,"M")+1)) -> 12 | AW24: =IF(AV24="","",(DATEDIF(AU24,AV24,"M")+1)) | AZ24: =IF(AY24="","",(DATEDIF(AX24,AY24,"M")+1)) | BC24: =IF(BB24="","",(DATEDIF(BA24,BB24,"M")+1)) | BD24: =IF(G24="Tetap","",IF(BA24<>"",BA24,IF(AX24<>"",AX24,IF(AU24<>"",AU24,IF(AR24<>"",AR24,IF(AO24<>"",AO24,IF(AL24<>"",AL24,IF(AI24<>"",AI24,"")))))))) -> 46235 | BE24: =IF($AI24="","0",(DATEDIF($AI24,TODAY(),"Y"))) -> 1 | BF24: =IF($AI24="","",(DATEDIF($AI24,TODAY(),"YM"))) -> 2 | BG24: =IF($AI24="","",(DATEDIF($AI24,TODAY(),"MD"))) -> 0
A25: =A24+1 -> 12 | B25: 55024 | C25: A03012 | D25: PS2SD | E25: BAMBANG SUPRIADI | F25: Sales | G25: =IF(AI25="","Perekrutan",IF(BE25>4,"Tetap",IF(BA25<>"","Kontrak VII",IF(AX25<>"","Kontrak VI",IF(AU25<>"","Kontrak V",IF(AR25<>"","Kontrak IV",IF(AO25<>"","Kontrak III",IF(AL25<>"","Kontrak II",IF(AI25<>"","Kontrak I",""))))))))) -> Tetap | H25: =IF(G25="Tetap","",IF(BA25<>"",BB25,IF(AX25<>"",AY25,IF(AU25<>"",AV25,IF(AR25<>"",AS25,IF(AO25<>"",AP25,IF(AL25<>"",AM25,IF(AI25<>"",AJ25,"")))))))) | I25: C | J25: 6 | K25: P.Siantar | L25: 1272020805780001 | M25: 1272022508090005 | N25: Islam | O25: P. Siantar | P25: 28618 | Q25: =IF(P25="","",(DATEDIF(P25,TODAY(),"Y"))) -> 48 | R25: Jl. Kiyai No. 54, RT 002 / RW 001, Kelurahan Bantan, Kecamatan Siantar Barat, Kota Pematangsiantar | S25: L | T25: Kawin | U25: K02 | Y25: 0812-6925-0670 | Z25: 834201165 | AA25: 780044442117000 | AB25: supriyadibemz@gmail.com | AI25: 39462 | AK25: =IF(AJ25="","",(DATEDIF(AI25,AJ25,"M")+1)) | AN25: =IF(AM25="","",(DATEDIF(AL25,AM25,"M")+1)) | AQ25: =IF(AP25="","",(DATEDIF(AO25,AP25,"M")+1)) | AT25: =IF(AS25="","",(DATEDIF(AR25,AS25,"M")+1)) | AW25: =IF(AV25="","",(DATEDIF(AU25,AV25,"M")+1)) | AZ25: =IF(AY25="","",(DATEDIF(AX25,AY25,"M")+1)) | BC25: =IF(BB25="","",(DATEDIF(BA25,BB25,"M")+1)) | BD25: =IF(G25="Tetap","",IF(BA25<>"",BA25,IF(AX25<>"",AX25,IF(AU25<>"",AU25,IF(AR25<>"",AR25,IF(AO25<>"",AO25,IF(AL25<>"",AL25,IF(AI25<>"",AI25,"")))))))) | BE25: =IF($AI25="","0",(DATEDIF($AI25,TODAY(),"Y"))) -> 18 | BF25: =IF($AI25="","",(DATEDIF($AI25,TODAY(),"YM"))) -> 8 | BG25: =IF($AI25="","",(DATEDIF($AI25,TODAY(),"MD"))) -> 18
A26: =A25+1 -> 13 | B26: 55025 | C26: A03013 | D26: PS2SD | E26: SYAMSUL RIZAL REZA | F26: Sales | G26: =IF(AI26="","Perekrutan",IF(BE26>4,"Tetap",IF(BA26<>"","Kontrak VII",IF(AX26<>"","Kontrak VI",IF(AU26<>"","Kontrak V",IF(AR26<>"","Kontrak IV",IF(AO26<>"","Kontrak III",IF(AL26<>"","Kontrak II",IF(AI26<>"","Kontrak I",""))))))))) -> Tetap | H26: =IF(G26="Tetap","",IF(BA26<>"",BB26,IF(AX26<>"",AY26,IF(AU26<>"",AV26,IF(AR26<>"",AS26,IF(AO26<>"",AP26,IF(AL26<>"",AM26,IF(AI26<>"",AJ26,"")))))))) | I26: B | J26: 5 | K26: P.Siantar | L26: 1208020911690001 | M26: 1208022903080084 | N26: Islam | O26: Bangun | P26: 25516 | Q26: =IF(P26="","",(DATEDIF(P26,TODAY(),"Y"))) -> 56 | R26: Jl. Asahan Km. 18,5 Huta II, RT 000 / RW 000, Kelurahan Pamatang Asilom, Kecamatan Gunung Malela, Kabupaten Simalungun | S26: L | T26: Kawin | U26: K03 | Y26: 0852-9745-3884 | Z26: 834520986 | AA26: 971488929117000 | AB26: samsulriall699@gmail.com | AC26: 27 Jun 2011 - 31 Jan 2012 | AI26: 40940 | AJ26: 41030 | AK26: =IF(AJ26="","",(DATEDIF(AI26,AJ26,"M")+1)) -> 4 | AL26: 41031 | AM26: 41396 | AN26: =IF(AM26="","",(DATEDIF(AL26,AM26,"M")+1)) -> 13 | AQ26: =IF(AP26="","",(DATEDIF(AO26,AP26,"M")+1)) | AT26: =IF(AS26="","",(DATEDIF(AR26,AS26,"M")+1)) | AW26: =IF(AV26="","",(DATEDIF(AU26,AV26,"M")+1)) | AZ26: =IF(AY26="","",(DATEDIF(AX26,AY26,"M")+1)) | BC26: =IF(BB26="","",(DATEDIF(BA26,BB26,"M")+1)) | BD26: =IF(G26="Tetap","",IF(BA26<>"",BA26,IF(AX26<>"",AX26,IF(AU26<>"",AU26,IF(AR26<>"",AR26,IF(AO26<>"",AO26,IF(AL26<>"",AL26,IF(AI26<>"",AI26,"")))))))) | BE26: =IF($AI26="","0",(DATEDIF($AI26,TODAY(),"Y"))) -> 14 | BF26: =IF($AI26="","",(DATEDIF($AI26,TODAY(),"YM"))) -> 8 | BG26: =IF($AI26="","",(DATEDIF($AI26,TODAY(),"MD"))) -> 2
A27: =A26+1 -> 14 | B27: 55026 | C27: A03014 | D27: PS2SD | E27: IMANSYAH SEMBIRING | F27: Sopir | G27: =IF(AI27="","Perekrutan",IF(BE27>4,"Tetap",IF(BA27<>"","Kontrak VII",IF(AX27<>"","Kontrak VI",IF(AU27<>"","Kontrak V",IF(AR27<>"","Kontrak IV",IF(AO27<>"","Kontrak III",IF(AL27<>"","Kontrak II",IF(AI27<>"","Kontrak I",""))))))))) -> Tetap | H27: =IF(G27="Tetap","",IF(BA27<>"",BB27,IF(AX27<>"",AY27,IF(AU27<>"",AV27,IF(AR27<>"",AS27,IF(AO27<>"",AP27,IF(AL27<>"",AM27,IF(AI27<>"",AJ27,"")))))))) | I27: - | J27: - | K27: P.Siantar | L27: 1207261410750001 | M27: 1271062312130003 | N27: Islam | O27: Medan | P27: 27681 | Q27: =IF(P27="","",(DATEDIF(P27,TODAY(),"Y"))) -> 50 | R27: Jl. Medan Km 4.5 Gg Mesjid No.24, RT 001 / RW 001, Kelurahan Naga Pita, Kecamatan Siantar Martoba, Kota Pematangsiantar | S27: L | T27: Kawin | U27: K0 | Y27: 0812-6049-7934 | Z27: 834356324 | AA27: 974184186125000 | AB27: sembiringimansyahsembiring@gmail.com | AC27: 26 Sep 2011 - 30 Apr 2012 | AI27: 41030 | AJ27: 41122 | AK27: =IF(AJ27="","",(DATEDIF(AI27,AJ27,"M")+1)) -> 4 | AL27: 41123 | AM27: 41488 | AN27: =IF(AM27="","",(DATEDIF(AL27,AM27,"M")+1)) -> 13 | AQ27: =IF(AP27="","",(DATEDIF(AO27,AP27,"M")+1)) | AT27: =IF(AS27="","",(DATEDIF(AR27,AS27,"M")+1)) | AW27: =IF(AV27="","",(DATEDIF(AU27,AV27,"M")+1)) | AZ27: =IF(AY27="","",(DATEDIF(AX27,AY27,"M")+1)) | BC27: =IF(BB27="","",(DATEDIF(BA27,BB27,"M")+1)) | BD27: =IF(G27="Tetap","",IF(BA27<>"",BA27,IF(AX27<>"",AX27,IF(AU27<>"",AU27,IF(AR27<>"",AR27,IF(AO27<>"",AO27,IF(AL27<>"",AL27,IF(AI27<>"",AI27,"")))))))) | BE27: =IF($AI27="","0",(DATEDIF($AI27,TODAY(),"Y"))) -> 14 | BF27: =IF($AI27="","",(DATEDIF($AI27,TODAY(),"YM"))) -> 5 | BG27: =IF($AI27="","",(DATEDIF($AI27,TODAY(),"MD"))) -> 2
A28: =A27+1 -> 15 | B28: 55027 | C28: A03015 | D28: PS2SD | E28: ANDI RINALDI | F28: Sopir | G28: =IF(AI28="","Perekrutan",IF(BE28>4,"Tetap",IF(BA28<>"","Kontrak VII",IF(AX28<>"","Kontrak VI",IF(AU28<>"","Kontrak V",IF(AR28<>"","Kontrak IV",IF(AO28<>"","Kontrak III",IF(AL28<>"","Kontrak II",IF(AI28<>"","Kontrak I",""))))))))) -> Tetap | H28: =IF(G28="Tetap","",IF(BA28<>"",BB28,IF(AX28<>"",AY28,IF(AU28<>"",AV28,IF(AR28<>"",AS28,IF(AO28<>"",AP28,IF(AL28<>"",AM28,IF(AI28<>"",AJ28,"")))))))) | I28: - | J28: - | K28: P.Siantar | L28: 1272072903790002 | M28: 1272071108090001 | N28: Islam | O28: P. Siantar | P28: 28943 | Q28: =IF(P28="","",(DATEDIF(P28,TODAY(),"Y"))) -> 47 | R28: Jln. V. Yudha BTN B-2, RT 018 / RW 006, Kelurahan Bah Kapul,Kecamatan Siantar Sitalasari, Kota Pematangsiantar | S28: L | T28: Belum Kawin | Y28: 0852-7030-8007 | Z28: 834524562 | AA28: 8530067571117000 | AB28: andi.renaldi79@gmail.com | AI28: 41122 | AJ28: 41221 | AK28: =IF(AJ28="","",(DATEDIF(AI28,AJ28,"M")+1)) -> 4 | AL28: 41222 | AM28: 41586 | AN28: =IF(AM28="","",(DATEDIF(AL28,AM28,"M")+1)) -> 12 | AQ28: =IF(AP28="","",(DATEDIF(AO28,AP28,"M")+1)) | AT28: =IF(AS28="","",(DATEDIF(AR28,AS28,"M")+1)) | AW28: =IF(AV28="","",(DATEDIF(AU28,AV28,"M")+1)) | AZ28: =IF(AY28="","",(DATEDIF(AX28,AY28,"M")+1)) | BC28: =IF(BB28="","",(DATEDIF(BA28,BB28,"M")+1)) | BD28: =IF(G28="Tetap","",IF(BA28<>"",BA28,IF(AX28<>"",AX28,IF(AU28<>"",AU28,IF(AR28<>"",AR28,IF(AO28<>"",AO28,IF(AL28<>"",AL28,IF(AI28<>"",AI28,"")))))))) | BE28: =IF($AI28="","0",(DATEDIF($AI28,TODAY(),"Y"))) -> 14 | BF28: =IF($AI28="","",(DATEDIF($AI28,TODAY(),"YM"))) -> 2 | BG28: =IF($AI28="","",(DATEDIF($AI28,TODAY(),"MD"))) -> 2
A29: =A28+1 -> 16 | B29: 55028 | C29: A03016 | D29: PS2SD | E29: TUMPAK TUA RINALDO LUMBAN TOBING | F29: Sopir | G29: =IF(AI29="","Perekrutan",IF(BE29>4,"Tetap",IF(BA29<>"","Kontrak VII",IF(AX29<>"","Kontrak VI",IF(AU29<>"","Kontrak V",IF(AR29<>"","Kontrak IV",IF(AO29<>"","Kontrak III",IF(AL29<>"","Kontrak II",IF(AI29<>"","Kontrak I",""))))))))) -> Kontrak IV | H29: =IF(G29="Tetap","",IF(BA29<>"",BB29,IF(AX29<>"",AY29,IF(AU29<>"",AV29,IF(AR29<>"",AS29,IF(AO29<>"",AP29,IF(AL29<>"",AM29,IF(AI29<>"",AJ29,"")))))))) -> 46660 | I29: - | J29: - | K29: Kab. Dairi | L29: 1211011403870004 | M29: 1211132711190001 | N29: Islam | O29: Sidikalang | P29: 31850 | Q29: =IF(P29="","",(DATEDIF(P29,TODAY(),"Y"))) -> 39 | R29: Desa Karing, RT 000 / RW 000, Desa Karing, Kecamatan Berampu, Kabupaten Dairi | S29: L | T29: Kawin | U29: K01 | V29: SMK | Y29: 0838-3906-8487 | Z29: 1919655889 | AA29: 530388685128000 | AB29: zembrong1985@gmail.com | AC29: Sopir Lepas | AI29: 45916 | AJ29: 46053 | AK29: =IF(AJ29="","",(DATEDIF(AI29,AJ29,"M")+1)) -> 5 | AL29: 46054 | AM29: 46173 | AN29: =IF(AM29="","",(DATEDIF(AL29,AM29,"M")+1)) -> 4 | AO29: 46174 | AP29: 46295 | AQ29: =IF(AP29="","",(DATEDIF(AO29,AP29,"M")+1)) -> 4 | AR29: 46296 | AS29: 46660 | AT29: =IF(AS29="","",(DATEDIF(AR29,AS29,"M")+1)) -> 12 | AW29: =IF(AV29="","",(DATEDIF(AU29,AV29,"M")+1)) | AZ29: =IF(AY29="","",(DATEDIF(AX29,AY29,"M")+1)) | BC29: =IF(BB29="","",(DATEDIF(BA29,BB29,"M")+1)) | BD29: =IF(G29="Tetap","",IF(BA29<>"",BA29,IF(AX29<>"",AX29,IF(AU29<>"",AU29,IF(AR29<>"",AR29,IF(AO29<>"",AO29,IF(AL29<>"",AL29,IF(AI29<>"",AI29,"")))))))) -> 46296 | BE29: =IF($AI29="","0",(DATEDIF($AI29,TODAY(),"Y"))) -> 1 | BF29: =IF($AI29="","",(DATEDIF($AI29,TODAY(),"YM"))) -> 0 | BG29: =IF($AI29="","",(DATEDIF($AI29,TODAY(),"MD"))) -> 17
A30: 1 | B30: 55029 | C30: A04001 | D30: LLU | E30: SUGENG SANTOSO | F30: Ka. Area | G30: =IF(AI30="","Perekrutan",IF(BE30>4,"Tetap",IF(BA30<>"","Kontrak VII",IF(AX30<>"","Kontrak VI",IF(AU30<>"","Kontrak V",IF(AR30<>"","Kontrak IV",IF(AO30<>"","Kontrak III",IF(AL30<>"","Kontrak II",IF(AI30<>"","Kontrak I",""))))))))) -> Tetap | H30: =IF(G30="Tetap","",IF(BA30<>"",BB30,IF(AX30<>"",AY30,IF(AU30<>"",AV30,IF(AR30<>"",AS30,IF(AO30<>"",AP30,IF(AL30<>"",AM30,IF(AI30<>"",AJ30,"")))))))) | K30: Malang | L30: 1104112606700002 | N30: Islam | O30: Probolinggo | P30: 25745 | Q30: =IF(P30="","",(DATEDIF(P30,TODAY(),"Y"))) -> 56 | R30: Simpang 4 Gunung Bukit Kebanyakan Aceh Tengah | S30: L | T30: Kawin | U30: K01 | Z30: 1130012192 | AA30: 1104112606700002 | AC30: 09 2007 – 21 Juli 2007 | AI30: 39286 | AJ30: 39469 | AK30: =IF(AJ30="","",(DATEDIF(AI30,AJ30,"M")+1)) -> 6 | AL30: 39470 | AM30: 39651 | AN30: =IF(AM30="","",(DATEDIF(AL30,AM30,"M")+1)) -> 6 | AQ30: =IF(AP30="","",(DATEDIF(AO30,AP30,"M")+1)) | AT30: =IF(AS30="","",(DATEDIF(AR30,AS30,"M")+1)) | AW30: =IF(AV30="","",(DATEDIF(AU30,AV30,"M")+1)) | AZ30: =IF(AY30="","",(DATEDIF(AX30,AY30,"M")+1)) | BC30: =IF(BB30="","",(DATEDIF(BA30,BB30,"M")+1)) | BD30: =IF(G30="Tetap","",IF(BA30<>"",BA30,IF(AX30<>"",AX30,IF(AU30<>"",AU30,IF(AR30<>"",AR30,IF(AO30<>"",AO30,IF(AL30<>"",AL30,IF(AI30<>"",AI30,"")))))))) | BE30: =IF($AI30="","0",(DATEDIF($AI30,TODAY(),"Y"))) -> 19 | BF30: =IF($AI30="","",(DATEDIF($AI30,TODAY(),"YM"))) -> 2 | BG30: =IF($AI30="","",(DATEDIF($AI30,TODAY(),"MD"))) -> 10
A31: =A30+1 -> 2 | B31: 55002 | C31: A01002 | D31: LLU | E31: RUDI ANTONI | F31: Sales Executive Taking Order | G31: =IF(AI31="","Perekrutan",IF(BE31>4,"Tetap",IF(BA31<>"","Kontrak VII",IF(AX31<>"","Kontrak VI",IF(AU31<>"","Kontrak V",IF(AR31<>"","Kontrak IV",IF(AO31<>"","Kontrak III",IF(AL31<>"","Kontrak II",IF(AI31<>"","Kontrak I",""))))))))) -> Kontrak IV | H31: =IF(G31="Tetap","",IF(BA31<>"",BB31,IF(AX31<>"",AY31,IF(AU31<>"",AV31,IF(AR31<>"",AS31,IF(AO31<>"",AP31,IF(AL31<>"",AM31,IF(AI31<>"",AJ31,"")))))))) -> 46477 | I31: A | J31: 9 | K31: Kab. Labuhanbatu | L31: 1222012102850003 | N31: Islam | O31: Gunung Melayu | P31: 31099 | Q31: =IF(P31="","",(DATEDIF(P31,TODAY(),"Y"))) -> 41 | R31: Jl. Manap Lubis Kampung Sawah RT / RW 0 Desa Sirandorung Kec. Rantau Utara Kab. Labuhanbatu Sumatera Utara | S31: L | T31: Kawin | U31: K02 | V31: SMA | Z31: 1799827455 | AA31: 1222012102850003 | AC31: Freelance | AI31: 45505 | AJ31: 45626 | AK31: =IF(AJ31="","",(DATEDIF(AI31,AJ31,"M")+1)) -> 4 | AL31: 45627 | AM31: 45991 | AN31: =IF(AM31="","",(DATEDIF(AL31,AM31,"M")+1)) -> 12 | AO31: 45992 | AP31: 46112 | AQ31: =IF(AP31="","",(DATEDIF(AO31,AP31,"M")+1)) -> 4 | AR31: 46113 | AS31: 46477 | AT31: =IF(AS31="","",(DATEDIF(AR31,AS31,"M")+1)) -> 12 | AW31: =IF(AV31="","",(DATEDIF(AU31,AV31,"M")+1)) | AZ31: =IF(AY31="","",(DATEDIF(AX31,AY31,"M")+1)) | BC31: =IF(BB31="","",(DATEDIF(BA31,BB31,"M")+1)) | BD31: =IF(G31="Tetap","",IF(BA31<>"",BA31,IF(AX31<>"",AX31,IF(AU31<>"",AU31,IF(AR31<>"",AR31,IF(AO31<>"",AO31,IF(AL31<>"",AL31,IF(AI31<>"",AI31,"")))))))) -> 46113 | BE31: =IF($AI31="","0",(DATEDIF($AI31,TODAY(),"Y"))) -> 2 | BF31: =IF($AI31="","",(DATEDIF($AI31,TODAY(),"YM"))) -> 2 | BG31: =IF($AI31="","",(DATEDIF($AI31,TODAY(),"MD"))) -> 2
A32: =A31+1 -> 3 | B32: 55030 | C32: A04002 | D32: LLU | E32: RIDHO FUSANTO | F32: Sales Executive (Dropping) | G32: =IF(AI32="","Perekrutan",IF(BE32>4,"Tetap",IF(BA32<>"","Kontrak VII",IF(AX32<>"","Kontrak VI",IF(AU32<>"","Kontrak V",IF(AR32<>"","Kontrak IV",IF(AO32<>"","Kontrak III",IF(AL32<>"","Kontrak II",IF(AI32<>"","Kontrak I",""))))))))) -> Tetap | H32: =IF(G32="Tetap","",IF(BA32<>"",BB32,IF(AX32<>"",AY32,IF(AU32<>"",AV32,IF(AR32<>"",AS32,IF(AO32<>"",AP32,IF(AL32<>"",AM32,IF(AI32<>"",AJ32,"")))))))) | I32: A | J32: 9 | K32: Kab. Labuhanbatu | L32: 1210141109910001 | N32: Islam | O32: Sidodadi | P32: 33492 | Q32: =IF(P32="","",(DATEDIF(P32,TODAY(),"Y"))) -> 35 | R32: Dusun Sidodadi B RT / RW 000 Desa Kampung Padang Kec. Pangkatan Kab. Labuhanbatu | S32: L | T32: Kawin | U32: K02 | V32: SMK | Z32: 916091091 | AA32: 1210141109910001 | AC32: Dari GBP 09 Sep 2024 | AI32: 43899 | AJ32: 09 Sep 24 - 31 Jan 2025 (9 Mar 2020) | AK32: =IF(AJ32="","",(DATEDIF(AI32,AJ32,"M")+1)) -> #VALUE! | AL32: 45689 | AM32: 45747 | AN32: =IF(AM32="","",(DATEDIF(AL32,AM32,"M")+1)) -> 2 | AQ32: =IF(AP32="","",(DATEDIF(AO32,AP32,"M")+1)) | AT32: =IF(AS32="","",(DATEDIF(AR32,AS32,"M")+1)) | AW32: =IF(AV32="","",(DATEDIF(AU32,AV32,"M")+1)) | AZ32: =IF(AY32="","",(DATEDIF(AX32,AY32,"M")+1)) | BC32: =IF(BB32="","",(DATEDIF(BA32,BB32,"M")+1)) | BD32: =IF(G32="Tetap","",IF(BA32<>"",BA32,IF(AX32<>"",AX32,IF(AU32<>"",AU32,IF(AR32<>"",AR32,IF(AO32<>"",AO32,IF(AL32<>"",AL32,IF(AI32<>"",AI32,"")))))))) | BE32: =IF($AI32="","0",(DATEDIF($AI32,TODAY(),"Y"))) -> 6 | BF32: =IF($AI32="","",(DATEDIF($AI32,TODAY(),"YM"))) -> 6 | BG32: =IF($AI32="","",(DATEDIF($AI32,TODAY(),"MD"))) -> 24
A33: =A32+1 -> 4 | B33: 55031 | C33: A04003 | D33: LLU | E33: THERESIA WIDI ASTUTY | F33: Administrasi Penjualan & Gudang (Kecil) Area | G33: =IF(AI33="","Perekrutan",IF(BE33>4,"Tetap",IF(BA33<>"","Kontrak VII",IF(AX33<>"","Kontrak VI",IF(AU33<>"","Kontrak V",IF(AR33<>"","Kontrak IV",IF(AO33<>"","Kontrak III",IF(AL33<>"","Kontrak II",IF(AI33<>"","Kontrak I",""))))))))) -> Tetap | H33: =IF(G33="Tetap","",IF(BA33<>"",BB33,IF(AX33<>"",AY33,IF(AU33<>"",AV33,IF(AR33<>"",AS33,IF(AO33<>"",AP33,IF(AL33<>"",AM33,IF(AI33<>"",AJ33,"")))))))) | I33: A | J33: 3 | K33: Kab. Labuhanbatu | L33: 1210015306860002 | N33: Kristen | O33: Rantauprapat | P33: 31576 | Q33: =IF(P33="","",(DATEDIF(P33,TODAY(),"Y"))) -> 40 | R33: Kompleks SMP N 3 RT / RW 000 Desa Padang Matinggi Kec. Rantau Utara, Kab. Labuhanbatu | S33: P | T33: Belum Kawin | U33: - | V33: S1 Akuntansi | Z33: 903257383 | AA33: 1210015306860002 | AC33: Dari GBP 09 Sep 2024 | AI33: 43862 | AJ33: 09 Sep 24 - 31 Jan 2025 ( 01 Feb 2020 ) | AK33: =IF(AJ33="","",(DATEDIF(AI33,AJ33,"M")+1)) -> #VALUE! | AN33: =IF(AM33="","",(DATEDIF(AL33,AM33,"M")+1)) | AQ33: =IF(AP33="","",(DATEDIF(AO33,AP33,"M")+1)) | AT33: =IF(AS33="","",(DATEDIF(AR33,AS33,"M")+1)) | AW33: =IF(AV33="","",(DATEDIF(AU33,AV33,"M")+1)) | AZ33: =IF(AY33="","",(DATEDIF(AX33,AY33,"M")+1)) | BC33: =IF(BB33="","",(DATEDIF(BA33,BB33,"M")+1)) | BD33: =IF(G33="Tetap","",IF(BA33<>"",BA33,IF(AX33<>"",AX33,IF(AU33<>"",AU33,IF(AR33<>"",AR33,IF(AO33<>"",AO33,IF(AL33<>"",AL33,IF(AI33<>"",AI33,"")))))))) | BE33: =IF($AI33="","0",(DATEDIF($AI33,TODAY(),"Y"))) -> 6 | BF33: =IF($AI33="","",(DATEDIF($AI33,TODAY(),"YM"))) -> 8 | BG33: =IF($AI33="","",(DATEDIF($AI33,TODAY(),"MD"))) -> 2
